<?xml version="1.0"?>
<robot name="robot_description">
  <link name="world"/>
  <joint name="robot_to_world" type="fixed">
    <parent link="world"/>
    <child link="link0"/>
    <origin rpy="0.0 0.0 0.0" xyz="0.0 0.0 0.1"/>
  </joint>
  <!-- end for simulation -->
  <link name="link0">
    <visual>
      <geometry>
        <sphere radius="0.1"/>
      </geometry>
    </visual>
    <collision>
      <geometry>
        <sphere radius="0.1"/>
      </geometry>
    </collision>
    <!-- for simulation -->
    <inertial>
      <origin rpy="0 0 0" xyz="0 0 0.05"/>
      <mass value="1.00"/>
      <inertia ixx="0.25083" ixy="0.0" ixz="0.0" iyy="0.25083" iyz="0.0" izz="0.5"/>
    </inertial>
    <!-- end for simulation -->
  </link>
  <link name="link1">
    <visual>
      <origin xyz="0 0 0.6" rpy="0 0 0"/>
      <geometry>
        <cylinder length="1.0" radius="0.1"/>
      </geometry>
    </visual>
    <collision>
      <origin xyz="0 0 0.6" rpy="0 0 0"/>
      <geometry>
        <cylinder length="1.0" radius="0.1"/>
      </geometry>
    </collision>
    <!-- for simulation -->
    <inertial>
      <origin rpy="0 0 0" xyz="0 0 0.5"/>
      <mass value="1.0"/>
      <inertia ixx="0.0858" ixy="0.0" ixz="0.0" iyy="0.0858" iyz="0.0" izz="0.005"/>
    </inertial>
    <!-- end for simulation -->
  </link>
  <link name="link_torso">
    <visual>
      <origin xyz="0 0 0.6" rpy="0 0 0"/>
      <geometry>
        <cylinder length="1.0" radius="0.1"/>
      </geometry>
    </visual>
    <collision>
      <origin xyz="0 0 0.6" rpy="0 0 0"/>
      <geometry>
        <cylinder length="1.0" radius="0.1"/>
      </geometry>
    </collision>
    <!-- for simulation -->
    <inertial>
      <origin rpy="0 0 0" xyz="0 0 0.5"/>
      <mass value="1.0"/>
      <inertia ixx="0.0858" ixy="0.0" ixz="0.0" iyy="0.0858" iyz="0.0" izz="0.005"/>
    </inertial>
    <!-- end for simulation -->
  </link>
  <joint name="joint_torso" type="fixed">
    <origin rpy="1.57 0 0" xyz="0 0.6 1.2"/>
    <parent link="link1"/>
    <child link="link_torso"/>
  </joint>
  <link name="link2">
    <visual>
      <origin xyz="0 0 0.6" rpy="0 0 0"/>
      <geometry>
        <cylinder length="1.0" radius="0.1"/>
      </geometry>
    </visual>
    <collision>
      <origin xyz="0 0 0.6" rpy="0 0 0"/>
      <geometry>
        <cylinder length="1.0" radius="0.1"/>
      </geometry>
    </collision>
    <!-- for simulation -->
    <inertial>
      <origin rpy="0 0 0" xyz="0 0 0.5"/>
      <mass value="1.0"/>
      <inertia ixx="0.0858" ixy="0.0" ixz="0.0" iyy="0.0858" iyz="0.0" izz="0.005"/>
    </inertial>
    <!-- end for simulation -->
  </link>
  <link name="link3">
    <visual>
      <origin xyz="0 0 0.6" rpy="0 0 0"/>
      <geometry>
        <cylinder length="1.0" radius="0.1"/>
      </geometry>
    </visual>
    <collision>
      <origin xyz="0 0 0.6" rpy="0 0 0"/>
      <geometry>
        <cylinder length="1.0" radius="0.1"/>
      </geometry>
    </collision>
    <!-- for simulation -->
    <inertial>
      <origin rpy="0 0 0" xyz="0 0 0.5"/>
      <mass value="1.0"/>
      <inertia ixx="0.0858" ixy="0.0" ixz="0.0" iyy="0.0858" iyz="0.0" izz="0.005"/>
    </inertial>
    <!-- end for simulation -->
  </link>
  <link name="link4">
    <visual>
      <origin xyz="0 0 0.6" rpy="0 0 0"/>
      <geometry>
        <cylinder length="1.0" radius="0.1"/>
      </geometry>
    </visual>
    <collision>
      <origin xyz="0 0 0.6" rpy="0 0 0"/>
      <geometry>
        <cylinder length="1.0" radius="0.1"/>
      </geometry>
    </collision>
    <!-- for simulation -->
    <inertial>
      <origin rpy="0 0 0" xyz="0 0 0.5"/>
      <mass value="1.0"/>
      <inertia ixx="0.0858" ixy="0.0" ixz="0.0" iyy="0.0858" iyz="0.0" izz="0.005"/>
    </inertial>
    <!-- end for simulation -->
  </link>
  <link name="link5">
    <visual>
      <origin xyz="0 0 0.6" rpy="0 0 0"/>
      <geometry>
        <cylinder length="1.0" radius="0.1"/>
      </geometry>
    </visual>
    <collision>
      <origin xyz="0 0 0.6" rpy="0 0 0"/>
      <geometry>
        <cylinder length="1.0" radius="0.1"/>
      </geometry>
    </collision>
    <!-- for simulation -->
    <inertial>
      <origin rpy="0 0 0" xyz="0 0 0.5"/>
      <mass value="1.0"/>
      <inertia ixx="0.0858" ixy="0.0" ixz="0.0" iyy="0.0858" iyz="0.0" izz="0.005"/>
    </inertial>
    <!-- end for simulation -->
  </link>
  <joint name="joint1" type="revolute">
    <safety_controller k_position="100.0" k_velocity="40.0" soft_lower_limit="-2.8973" soft_upper_limit="2.8973"/>
    <origin rpy="0 0 0" xyz="0 0 0.0"/>
    <parent link="link0"/>
    <child link="link1"/>
    <axis xyz="1 0 0"/>
    <limit effort="87" lower="-2.8973" upper="2.8973" velocity="2.1750"/>
    <!-- for simulation -->
    <dynamics damping="0.0" friction="0.0"/>
    <!-- end for simulation -->
  </joint>
  <joint name="joint2" type="revolute">
    <safety_controller k_position="100.0" k_velocity="40.0" soft_lower_limit="-2.8973" soft_upper_limit="2.8973"/>
    <origin rpy="0 0 0" xyz="0 0.6 1.2"/>
    <parent link="link1"/>
    <child link="link2"/>
    <axis xyz="0 1 0"/>
    <limit effort="87" lower="-2.8973" upper="2.8973" velocity="2.1750"/>
    <!-- for simulation -->
    <dynamics damping="0.0" friction="0.0"/>
    <!-- end for simulation -->
  </joint>
  <joint name="joint3" type="revolute">
    <safety_controller k_position="100.0" k_velocity="40.0" soft_lower_limit="-2.8973" soft_upper_limit="2.8973"/>
    <origin rpy="0 0 0" xyz="0 0 1.1"/>
    <parent link="link2"/>
    <child link="link3"/>
    <axis xyz="1 0 0"/>
    <limit effort="87" lower="-2.8973" upper="2.8973" velocity="2.1750"/>
    <!-- for simulation -->
    <dynamics damping="0.0" friction="0.0"/>
    <!-- end for simulation -->
  </joint>
  <link name="ee1_link">
    <visual>
      <origin xyz="0 0 0.005" rpy="0 0 0"/>
      <geometry>
        <sphere radius="0.1"/>
      </geometry>
    </visual>
    <collision>
      <geometry>
        <sphere radius="0.1"/>
      </geometry>
    </collision>
    <!-- for simulation -->
    <inertial>
      <origin rpy="0 0 0" xyz="0 0 0.005"/>
      <mass value="0.0001"/>
      <inertia ixx="0.00005" ixy="0.0" ixz="0.0" iyy="0.00005" iyz="0.0" izz="0.00005"/>
    </inertial>
    <!-- end for simulation -->
  </link>
  <joint name="joint4" type="fixed">
    <origin rpy="0 0 0" xyz="0 0 1.2"/>
    <parent link="link3"/>
    <child link="ee1_link"/>
    <axis xyz="0 0 1"/>
  </joint>
  <!-- end for simulation -->
  <joint name="joint5" type="revolute">
    <safety_controller k_position="100.0" k_velocity="40.0" soft_lower_limit="-2.8973" soft_upper_limit="2.8973"/>
    <origin rpy="0 0 0" xyz="0 -0.6 1.2"/>
    <parent link="link1"/>
    <child link="link4"/>
    <axis xyz="0 1 0"/>
    <limit effort="87" lower="-2.8973" upper="2.8973" velocity="2.1750"/>
    <!-- for simulation -->
    <dynamics damping="0.0" friction="0.0"/>
    <!-- end for simulation -->
  </joint>
  <joint name="joint6" type="revolute">
    <safety_controller k_position="100.0" k_velocity="40.0" soft_lower_limit="-2.8973" soft_upper_limit="2.8973"/>
    <origin rpy="0 0 0" xyz="0 0 1.1"/>
    <parent link="link4"/>
    <child link="link5"/>
    <axis xyz="1 0 0"/>
    <limit effort="87" lower="-2.8973" upper="2.8973" velocity="2.1750"/>
    <!-- for simulation -->
    <dynamics damping="0.0" friction="0.0"/>
    <!-- end for simulation -->
  </joint>
  <link name="ee2_link">
    <visual>
      <origin xyz="0 0 0.005" rpy="0 0 0"/>
      <geometry>
        <sphere radius="0.1"/>
      </geometry>
    </visual>
    <collision>
      <geometry>
        <sphere radius="0.1"/>
      </geometry>
    </collision>
    <!-- for simulation -->
    <inertial>
      <origin rpy="0 0 0" xyz="0 0 0.005"/>
      <mass value="0.0001"/>
      <inertia ixx="0.00005" ixy="0.0" ixz="0.0" iyy="0.00005" iyz="0.0" izz="0.00005"/>
    </inertial>
    <!-- end for simulation -->
  </link>
  <joint name="joint7" type="fixed">
    <origin rpy="0 0 0" xyz="0 0 1.2"/>
    <parent link="link5"/>
    <child link="ee2_link"/>
    <axis xyz="0 0 1"/>
  </joint>
  <!-- end for simulation -->
</robot>
