<?xml version="1.0"?>
<!-- =================================================================================== -->
<!-- |    This document was autogenerated by xacro from nlink.urdf.xacro               | -->
<!-- |    EDITING THIS FILE BY HAND IS NOT RECOMMENDED                                 | -->
<!-- =================================================================================== -->
<robot name="nLink">
  <link name="world"/>
  <link name="base">
    <visual>
      <origin rpy="0 0 0" xyz="0 0 0.05"/>
      <geometry>
        <cylinder length="0.1" radius="0.3"/>
      </geometry>
    </visual>
    <collision>
      <origin rpy="0 0 0" xyz="0 0 0.05"/>
      <geometry>
        <cylinder length="0.1" radius="0.3"/>
      </geometry>
    </collision>
    <inertial>
      <origin rpy="0 0 0" xyz="0 0 0.05"/>
      <mass value="1.0"/>
      <inertia ixx="0.0233333333333" ixy="0.0" ixz="0.0" iyy="0.0233333333333" iyz="0.0" izz="0.045"/>
    </inertial>
  </link>
  <link name="link1">
    <visual>
      <origin rpy="0 0 0" xyz="0 0 0.15"/>
      <geometry>
        <cylinder length="0.3" radius="0.1"/>
      </geometry>
    </visual>
    <collision>
      <origin rpy="0 0 0" xyz="0 0 0.15"/>
      <geometry>
        <cylinder length="0.3" radius="0.1"/>
      </geometry>
    </collision>
    <inertial>
      <origin rpy="0 0 0" xyz="0 0 0.15"/>
      <mass value="1.0"/>
      <inertia ixx="0.01" ixy="0.0" ixz="0.0" iyy="0.01" iyz="0.0" izz="0.005"/>
    </inertial>
  </link>
  <link name="link2">
    <visual>
      <origin rpy="0 0 0" xyz="0 0 0.05"/>
      <geometry>
        <cylinder length="0.1" radius="0.1"/>
      </geometry>
    </visual>
    <collision>
      <origin rpy="0 0 0" xyz="0 0 0.05"/>
      <geometry>
        <cylinder length="0.1" radius="0.1"/>
      </geometry>
    </collision>
    <inertial>
      <origin rpy="0 0 0" xyz="0 0 0.05"/>
      <mass value="1.0"/>
      <inertia ixx="0.00333333333333" ixy="0.0" ixz="0.0" iyy="0.00333333333333" iyz="0.0" izz="0.005"/>
    </inertial>
  </link>
  <link name="link3">
    <visual>
      <origin rpy="0 0 0" xyz="0 0 0.15"/>
      <geometry>
        <cylinder length="0.3" radius="0.1"/>
      </geometry>
    </visual>
    <collision>
      <origin rpy="0 0 0" xyz="0 0 0.15"/>
      <geometry>
        <cylinder length="0.3" radius="0.1"/>
      </geometry>
    </collision>
    <inertial>
      <origin rpy="0 0 0" xyz="0 0 0.15"/>
      <mass value="1.0"/>
      <inertia ixx="0.01" ixy="0.0" ixz="0.0" iyy="0.01" iyz="0.0" izz="0.005"/>
    </inertial>
  </link>
  <link name="link4">
    <visual>
      <origin rpy="0 0 0" xyz="0 0 0.05"/>
      <geometry>
        <cylinder length="0.1" radius="0.1"/>
      </geometry>
    </visual>
    <collision>
      <origin rpy="0 0 0" xyz="0 0 0.05"/>
      <geometry>
        <cylinder length="0.1" radius="0.1"/>
      </geometry>
    </collision>
    <inertial>
      <origin rpy="0 0 0" xyz="0 0 0.05"/>
      <mass value="1.0"/>
      <inertia ixx="0.00333333333333" ixy="0.0" ixz="0.0" iyy="0.00333333333333" iyz="0.0" izz="0.005"/>
    </inertial>
  </link>
  <link name="link5">
    <visual>
      <origin rpy="0 0 0" xyz="0 0 0.15"/>
      <geometry>
        <cylinder length="0.3" radius="0.1"/>
      </geometry>
    </visual>
    <collision>
      <origin rpy="0 0 0" xyz="0 0 0.15"/>
      <geometry>
        <cylinder length="0.3" radius="0.1"/>
      </geometry>
    </collision>
    <inertial>
      <origin rpy="0 0 0" xyz="0 0 0.15"/>
      <mass value="1.0"/>
      <inertia ixx="0.01" ixy="0.0" ixz="0.0" iyy="0.01" iyz="0.0" izz="0.005"/>
    </inertial>
  </link>
  <link name="link6">
    <visual>
      <origin rpy="0 0 0" xyz="0 0 0.05"/>
      <geometry>
        <cylinder length="0.1" radius="0.1"/>
      </geometry>
    </visual>
    <collision>
      <origin rpy="0 0 0" xyz="0 0 0.05"/>
      <geometry>
        <cylinder length="0.1" radius="0.1"/>
      </geometry>
    </collision>
    <inertial>
      <origin rpy="0 0 0" xyz="0 0 0.05"/>
      <mass value="1.0"/>
      <inertia ixx="0.00333333333333" ixy="0.0" ixz="0.0" iyy="0.00333333333333" iyz="0.0" izz="0.005"/>
    </inertial>
  </link>
  <link name="link7">
    <visual>
      <origin rpy="0 0 0" xyz="0 0 0.15"/>
      <geometry>
        <cylinder length="0.3" radius="0.1"/>
      </geometry>
    </visual>
    <collision>
      <origin rpy="0 0 0" xyz="0 0 0.15"/>
      <geometry>
        <cylinder length="0.3" radius="0.1"/>
      </geometry>
    </collision>
    <inertial>
      <origin rpy="0 0 0" xyz="0 0 0.15"/>
      <mass value="1.0"/>
      <inertia ixx="0.01" ixy="0.0" ixz="0.0" iyy="0.01" iyz="0.0" izz="0.005"/>
    </inertial>
  </link>
  <link name="linkee">
    <visual>
      <origin rpy="0 0 0" xyz="0 0 0.15"/>
      <geometry>
        <cylinder length="0.3" radius="0.01"/>
      </geometry>
    </visual>
    <collision>
      <origin rpy="0 0 0" xyz="0 0 0.15"/>
      <geometry>
        <cylinder length="0.3" radius="0.01"/>
      </geometry>
    </collision>
    <inertial>
      <origin rpy="0 0 0" xyz="0 0 0.15"/>
      <mass value="1.0"/>
      <inertia ixx="0.007525" ixy="0.0" ixz="0.0" iyy="0.007525" iyz="0.0" izz="5e-05"/>
    </inertial>
  </link>
  <joint name="jointworldBase" type="fixed">
    <safety_controller k_position="100.0" k_velocity="40.0" soft_lower_limit="-2.8973" soft_upper_limit="2.8973"/>
    <origin rpy="0 0 0" xyz="0 0 0.0"/>
    <parent link="world"/>
    <child link="base"/>
    <axis xyz="1 0 0"/>
    <limit effort="87" lower="-1.57079632679" upper="1.57079632679" velocity="2.0"/>
    <dynamics damping="0.0" friction="0.0"/>
  </joint>
  <joint name="jointjoint0" type="revolute">
    <safety_controller k_position="100.0" k_velocity="40.0" soft_lower_limit="-2.8973" soft_upper_limit="2.8973"/>
    <origin rpy="0 0 0" xyz="0 0 0.1"/>
    <parent link="base"/>
    <child link="link1"/>
    <axis xyz="0 0 1"/>
    <limit effort="87" lower="-1.57079632679" upper="1.57079632679" velocity="2.0"/>
    <dynamics damping="0.0" friction="0.0"/>
  </joint>
  <joint name="jointjoint1" type="revolute">
    <safety_controller k_position="100.0" k_velocity="40.0" soft_lower_limit="-2.8973" soft_upper_limit="2.8973"/>
    <origin rpy="0 1.57079632679 0" xyz="-0.05 0 0.40"/>
    <parent link="link1"/>
    <child link="link2"/>
    <axis xyz="0 0 1"/>
    <limit effort="87" lower="-1.57079632679" upper="1.57079632679" velocity="2.0"/>
    <dynamics damping="0.0" friction="0.0"/>
  </joint>
  <joint name="jointjoint2" type="revolute">
    <safety_controller k_position="100.0" k_velocity="40.0" soft_lower_limit="-2.8973" soft_upper_limit="2.8973"/>
    <origin rpy="0 -1.57079632679 0" xyz="-0.10 0 0.05"/>
    <parent link="link2"/>
    <child link="link3"/>
    <axis xyz="0 0 1"/>
    <limit effort="87" lower="-1.57079632679" upper="1.57079632679" velocity="2.0"/>
    <dynamics damping="0.0" friction="0.0"/>
  </joint>
  <joint name="jointjoint3" type="revolute">
    <safety_controller k_position="100.0" k_velocity="40.0" soft_lower_limit="-2.8973" soft_upper_limit="2.8973"/>
    <origin rpy="0 1.57079632679 0" xyz="-0.05 0 0.40"/>
    <parent link="link3"/>
    <child link="link4"/>
    <axis xyz="0 0 1"/>
    <limit effort="87" lower="-1.57079632679" upper="1.57079632679" velocity="2.0"/>
    <dynamics damping="0.0" friction="0.0"/>
  </joint>
  <joint name="jointjoint4" type="revolute">
    <safety_controller k_position="100.0" k_velocity="40.0" soft_lower_limit="-2.8973" soft_upper_limit="2.8973"/>
    <origin rpy="0 -1.57079632679 0" xyz="-0.10 0 0.05"/>
    <parent link="link4"/>
    <child link="link5"/>
    <axis xyz="0 0 1"/>
    <limit effort="87" lower="-1.57079632679" upper="1.57079632679" velocity="2.0"/>
    <dynamics damping="0.0" friction="0.0"/>
  </joint>
  <joint name="jointjoint5" type="revolute">
    <safety_controller k_position="100.0" k_velocity="40.0" soft_lower_limit="-2.8973" soft_upper_limit="2.8973"/>
    <origin rpy="0 1.57079632679 0" xyz="-0.05 0 0.40"/>
    <parent link="link5"/>
    <child link="link6"/>
    <axis xyz="0 0 1"/>
    <limit effort="87" lower="-1.57079632679" upper="1.57079632679" velocity="2.0"/>
    <dynamics damping="0.0" friction="0.0"/>
  </joint>
  <joint name="jointjoint6" type="revolute">
    <safety_controller k_position="100.0" k_velocity="40.0" soft_lower_limit="-2.8973" soft_upper_limit="2.8973"/>
    <origin rpy="0 -1.57079632679 0" xyz="-0.10 0 0.05"/>
    <parent link="link6"/>
    <child link="link7"/>
    <axis xyz="0 0 1"/>
    <limit effort="87" lower="-1.57079632679" upper="1.57079632679" velocity="2.0"/>
    <dynamics damping="0.0" friction="0.0"/>
  </joint>
  <joint name="jointjointee" type="fixed">
    <safety_controller k_position="100.0" k_velocity="40.0" soft_lower_limit="-2.8973" soft_upper_limit="2.8973"/>
    <origin rpy="0 0 0" xyz="-0.00 0 0.20"/>
    <parent link="link7"/>
    <child link="linkee"/>
    <axis xyz="0 0 1"/>
    <limit effort="87" lower="-1.57079632679" upper="1.57079632679" velocity="2.0"/>
    <dynamics damping="0.0" friction="0.0"/>
  </joint>
</robot>

