<?xml version="1.0" encoding="utf-8"?>
<!-- =================================================================================== -->
<!-- |    This document was autogenerated by xacro from mmrobot.urdf.xacro             | -->
<!-- |    EDITING THIS FILE BY HAND IS NOT RECOMMENDED                                 | -->
<!-- =================================================================================== -->
<robot name="albert">
  <material name="Boxer_Black">
    <color rgba="0.1 0.1 0.1 1.0"/>
  </material>
  <material name="Boxer_Blue">
    <color rgba="0.0 0.0 0.8 1.0"/>
  </material>
  <material name="Boxer_Purple">
    <color rgba="0.6 0.0 0.6 1.0"/>
  </material>
  <material name="Boxer_Green">
    <color rgba="0.0 0.8 0.0 1.0"/>
  </material>
  <material name="Boxer_LimeGreen">
    <color rgba="0.3 0.8 0.3 1.0"/>
  </material>
  <material name="Boxer_Grey">
    <color rgba="0.5 0.5 0.5 1.0"/>
  </material>
  <material name="Boxer_DarkGrey">
    <color rgba="0.3 0.3 0.3 1.0"/>
  </material>
  <material name="Boxer_Red">
    <color rgba="0.8 0.0 0.0 1.0"/>
  </material>
  <material name="Boxer_Pink">
    <color rgba="0.8 0.4 0.8 1.0"/>
  </material>
  <material name="Boxer_White">
    <color rgba="1.0 1.0 1.0 1.0"/>
  </material>
  <material name="Boxer_Yellow">
    <color rgba="0.8 0.8 0.0 1.0"/>
  </material>
  <material name="Boxer_GreyTransparent">
    <color rgba="0.5 0.5 0.5 0.5"/>
  </material>
  <!-- end for simulation -->
  <!--xacro:panda_arm /-->
  <!--xacro:hand ns="panda" rpy="0 0 ${-pi/4}" connected_to="panda_link8"/-->
  <!-- for simulation -->
  <!--xacro:arg name="robot_name" default="panda"/-->
  <!--xacro:panda_gazebo robot_name="$(arg robot_name)" /-->
  <!--xacro:panda_transmission robot_name="$(arg robot_name)" load_hand="true" /-->
  <!-- end for simulation -->
  <link name="chassis_link">
    <inertial>
      <origin rpy="1.5708 0 0" xyz="0 0 0.07"/>
      <mass value="51"/>
      <inertia ixx="2.3" ixy="0" ixz="0" iyy="3.35" iyz="0.00" izz="1.22"/>
    </inertial>
    <visual>
      <origin rpy="0 0 0" xyz="0 0 0"/>
      <geometry>
        <mesh filename="meshes/visual/chassis_link.dae"/>
      </geometry>
      <material name="">
        <color rgba="0.8 0.8 0.9 1"/>
      </material>
    </visual>
    <collision>
      <origin rpy="0 0 0" xyz="0 0 0"/>
      <geometry>
        <mesh filename="meshes/collision/chassis_link.STL"/>
      </geometry>
    </collision>
  </link>
  <link name="internal_link">
    <inertial>
      <origin rpy="0 0 0" xyz="0 0.19 -0.031"/>
      <mass value="31"/>
      <inertia ixx="1.19" ixy="0" ixz="0" iyy="1.82" iyz="0.0" izz="0.68"/>
    </inertial>
    <visual>
      <origin rpy="0 0 0" xyz="0 0 0"/>
      <geometry>
        <mesh filename="meshes/visual/internal_link.dae"/>
      </geometry>
      <material name="Boxer_DarkGrey"/>
    </visual>
    <collision>
      <origin rpy="0 0 0" xyz="0 0 0"/>
      <geometry>
        <!-- Mesh is scaled down slightly in length, to mitigate collision with laser rays due to slow physics updates  -->
        <!-- (The z axis is scaled since the whole model is rotated at the joint, and collision model resolution isn't
      very smart.) -->
        <mesh filename="meshes/collision/internal_link.STL"/>
      </geometry>
    </collision>
  </link>
  <joint name="internal_joint" type="fixed">
    <origin rpy="1.5708 0 0" xyz="0 0 0"/>
    <parent link="chassis_link"/>
    <child link="internal_link"/>
    <axis xyz="0 0 0"/>
  </joint>
  <link name="lift_link">
    <inertial>
      <origin rpy="0 0 0" xyz="0 0.076 0"/>
      <mass value="10"/>
      <inertia ixx="0.47" ixy="0" ixz="0" iyy="0.74" iyz="0" izz="0.29"/>
    </inertial>
    <visual>
      <origin rpy="0 0 0" xyz="0 0 0"/>
      <geometry>
        <mesh filename="meshes/visual/lift_link.dae"/>
      </geometry>
      <material name="">
        <color rgba="0.8 0.8 0.9 1"/>
      </material>
    </visual>
    <collision>
      <origin rpy="0 0 0" xyz="0 0 0"/>
      <geometry>
        <mesh filename="meshes/collision/lift_link.STL"/>
      </geometry>
    </collision>
  </link>
  <joint name="lift_joint" type="prismatic">
    <origin rpy="1.5708 0 0" xyz="0 0 0.177"/>
    <parent link="chassis_link"/>
    <child link="lift_link"/>
    <axis xyz="0 1 0"/>
    <limit effort="10000.0" lower="0" upper="0.078" velocity="0.02"/>
    <dynamics damping="100.0" friction="100"/>
  </joint>
  <link name="top_mount_bottom">
    <inertial>
      <origin rpy="0 0 0" xyz="0 0 0"/>
      <mass value="10"/>
      <inertia ixx="0.50" ixy="0" ixz="0" iyy="0.50" iyz="0" izz="1.00"/>
    </inertial>
    <visual>
      <origin rpy="0 0 0" xyz="0 0 0"/>
      <geometry>
        <mesh filename="meshes/collision/top_plate.stl"/>
      </geometry>
      <material name="Boxer_DarkGrey"/>
    </visual>
    <collision>
      <origin rpy="0 0 0" xyz="0 0 0"/>
      <geometry>
        <mesh filename="meshes/collision/top_plate_collision.stl"/>
      </geometry>
    </collision>
  </link>
  <joint name="top_mount_bottom_joint" type="fixed">
    <origin rpy="0 -1.5707 -1.5707" xyz="0 0.1125 0"/>
    <parent link="lift_link"/>
    <child link="top_mount_bottom"/>
  </joint>
  <link name="extrusion1">
    <inertial>
      <origin rpy="0 0 0" xyz="0 0 0"/>
      <mass value="1"/>
      <inertia ixx="0.50" ixy="0" ixz="0" iyy="0.50" iyz="0" izz="0.20"/>
    </inertial>
    <visual>
      <origin rpy="0 0 0" xyz="0 0 0"/>
      <geometry>
        <mesh filename="meshes/collision/extrusion.stl"/>
      </geometry>
      <material name="Boxer_DarkGrey"/>
    </visual>
    <collision>
      <origin rpy="0 0 0" xyz="0 0 0"/>
      <geometry>
        <mesh filename="meshes/collision/extrusion.stl"/>
      </geometry>
    </collision>
  </link>
  <joint name="extrusion1_joint" type="fixed">
    <origin rpy="0 0 0" xyz="-0.2785 0.1835 0"/>
    <parent link="top_mount_bottom"/>
    <child link="extrusion1"/>
  </joint>
  <link name="extrusion2">
    <inertial>
      <origin rpy="0 0 0" xyz="0 0 0"/>
      <mass value="1"/>
      <inertia ixx="0.50" ixy="0" ixz="0" iyy="0.50" iyz="0" izz="0.20"/>
    </inertial>
    <visual>
      <origin rpy="0 0 0" xyz="0 0 0"/>
      <geometry>
        <mesh filename="meshes/collision/extrusion.stl"/>
      </geometry>
      <material name="Boxer_DarkGrey"/>
    </visual>
    <collision>
      <origin rpy="0 0 0" xyz="0 0 0"/>
      <geometry>
        <mesh filename="meshes/collision/extrusion.stl"/>
      </geometry>
    </collision>
  </link>
  <joint name="extrusion2_joint" type="fixed">
    <origin rpy="0 0 -1.5707" xyz="0.2785 0.1835 0"/>
    <parent link="top_mount_bottom"/>
    <child link="extrusion2"/>
  </joint>
  <link name="extrusion3">
    <inertial>
      <origin rpy="0 0 0" xyz="0 0 0"/>
      <mass value="1"/>
      <inertia ixx="0.50" ixy="0" ixz="0" iyy="0.50" iyz="0" izz="0.20"/>
    </inertial>
    <visual>
      <origin rpy="0 0 0" xyz="0 0 0"/>
      <geometry>
        <mesh filename="meshes/collision/extrusion.stl"/>
      </geometry>
      <material name="Boxer_DarkGrey"/>
    </visual>
    <collision>
      <origin rpy="0 0 0" xyz="0 0 0"/>
      <geometry>
        <mesh filename="meshes/collision/extrusion.stl"/>
      </geometry>
    </collision>
  </link>
  <joint name="extrusion3_joint" type="fixed">
    <origin rpy="0 0 3.1414" xyz="0.2785 -0.1835 0"/>
    <parent link="top_mount_bottom"/>
    <child link="extrusion3"/>
  </joint>
  <link name="extrusion4">
    <inertial>
      <origin rpy="0 0 0" xyz="0 0 0"/>
      <mass value="1"/>
      <inertia ixx="0.50" ixy="0" ixz="0" iyy="0.50" iyz="0" izz="0.20"/>
    </inertial>
    <visual>
      <origin rpy="0 0 0" xyz="0 0 0"/>
      <geometry>
        <mesh filename="meshes/collision/extrusion.stl"/>
      </geometry>
      <material name="Boxer_DarkGrey"/>
    </visual>
    <collision>
      <origin rpy="0 0 0" xyz="0 0 0"/>
      <geometry>
        <mesh filename="meshes/collision/extrusion.stl"/>
      </geometry>
    </collision>
  </link>
  <joint name="extrusion4_joint" type="fixed">
    <origin rpy="0 0 1.5707" xyz="-0.2785 -0.1835 0"/>
    <parent link="top_mount_bottom"/>
    <child link="extrusion4"/>
  </joint>
  <link name="top_mount">
    <inertial>
      <origin rpy="0 0 0" xyz="0 0 0"/>
      <mass value="10"/>
      <inertia ixx="0.50" ixy="0" ixz="0" iyy="0.50" iyz="0" izz="1.00"/>
    </inertial>
    <visual>
      <origin rpy="0 0 0" xyz="0 0 0"/>
      <geometry>
        <mesh filename="meshes/collision/top_plate.stl"/>
      </geometry>
      <material name="Boxer_DarkGrey"/>
    </visual>
    <collision>
      <origin rpy="0 0 0" xyz="0 0 0"/>
      <geometry>
        <mesh filename="meshes/collision/top_plate_collision.stl"/>
      </geometry>
    </collision>
  </link>
  <!-- 0.27 in z direction because extrusion is 0.30, and plate is 0.1 -->
  <joint name="top_mount_joint" type="fixed">
    <origin rpy="0 0 0" xyz="0.2785 -0.1835 0.31"/>
    <parent link="extrusion1"/>
    <child link="top_mount"/>
  </joint>
  <link name="rotacastor_right_link">
    <inertial>
      <origin rpy="0 0 0" xyz="0 0 0"/>
      <mass value="100"/>
      <inertia ixx="0.2" ixy="0" ixz="0" iyy="0.2" iyz="0" izz="0.2"/>
    </inertial>
    <visual>
      <origin rpy="0 1.5708 0" xyz="0 0 0"/>
      <geometry>
        <cylinder length="0.06" radius="0.0625"/>
      </geometry>
      <material name="Boxer_Red"/>
    </visual>
    <collision>
      <origin rpy="0 1.5708 0" xyz="0 0 0"/>
      <geometry>
        <cylinder length="0.001" radius="0.0625"/>
      </geometry>
    </collision>
  </link>
  <joint name="rotacastor_right_joint" type="continuous">
    <origin rpy="0 0 0" xyz="-0.177 -0.274 0.043"/>
    <parent link="chassis_link"/>
    <child link="rotacastor_right_link"/>
    <axis xyz="1 0 0"/>
    <dynamics damping="1.0"/>
  </joint>
  <link name="rotacastor_left_link">
    <inertial>
      <origin rpy="0 0 0" xyz="0 0 0"/>
      <mass value="100"/>
      <inertia ixx="0.2" ixy="0" ixz="0" iyy="0.2" iyz="0" izz="0.2"/>
    </inertial>
    <visual>
      <origin rpy="0 1.5708 0" xyz="0 0 0"/>
      <geometry>
        <cylinder length="0.06" radius="0.0625"/>
      </geometry>
      <material name="Boxer_Red"/>
    </visual>
    <collision>
      <origin rpy="0 1.5708 0" xyz="0 0 0"/>
      <geometry>
        <cylinder length="0.001" radius="0.0625"/>
      </geometry>
    </collision>
  </link>
  <joint name="rotacastor_left_joint" type="continuous">
    <origin rpy="0 0 0" xyz="0.177 -0.274 0.043"/>
    <parent link="chassis_link"/>
    <child link="rotacastor_left_link"/>
    <axis xyz="1 0 0"/>
    <dynamics damping="1.0"/>
  </joint>
  <link name="wheel_right_link">
    <inertial>
      <origin rpy="0 0 0" xyz="0 0 0"/>
      <mass value="100"/>
      <inertia ixx="0.2" ixy="0" ixz="0" iyy="0.2" iyz="0" izz="0.2"/>
    </inertial>
    <visual>
      <origin rpy="0 1.5708 0" xyz="0 0 0"/>
      <geometry>
        <cylinder length="0.05" radius="0.080"/>
      </geometry>
      <material name="Boxer_Red"/>
    </visual>
    <collision>
      <origin rpy="0 1.5708 0" xyz="0 0 0"/>
      <geometry>
        <cylinder length="0.001" radius="0.080"/>
      </geometry>
    </collision>
  </link>
  <joint name="wheel_right_joint" type="continuous">
    <origin rpy="0 0 0" xyz="-0.247 0.157 0.058"/>
    <parent link="chassis_link"/>
    <child link="wheel_right_link"/>
    <axis xyz="1 0 0"/>
    <limit effort="10000" velocity="1000"/>
    <dynamics damping="1.0"/>
  </joint>
  <link name="wheel_left_link">
    <inertial>
      <origin rpy="0 0 0" xyz="0 0 0"/>
      <mass value="100"/>
      <inertia ixx="0.2" ixy="0" ixz="0" iyy="0.2" iyz="0" izz="0.2"/>
    </inertial>
    <visual>
      <origin rpy="0 1.5708 0" xyz="0 0 0"/>
      <geometry>
        <cylinder length="0.05" radius="0.080"/>
      </geometry>
      <material name="Boxer_Red"/>
    </visual>
    <collision>
      <origin rpy="0 1.5708 0" xyz="0 0 0"/>
      <geometry>
        <cylinder length="0.001" radius="0.080"/>
      </geometry>
    </collision>
  </link>
  <joint name="wheel_left_joint" type="continuous">
    <origin rpy="0 0 0" xyz="0.247 0.157 0.058"/>
    <parent link="chassis_link"/>
    <child link="wheel_left_link"/>
    <axis xyz="1 0 0"/>
    <limit effort="10000" velocity="1000"/>
    <dynamics damping="1.0"/>
  </joint>
  <!-- Base link with no geometry or inertia, because KDL needs it
to be that way. -->
  <link name="base_link">
    <inertial>
      <origin rpy="0 0 0" xyz="0 0 0"/>
      <mass value="1"/>
      <inertia ixx="0.2" ixy="0" ixz="0" iyy="0.2" iyz="0" izz="0.2"/>
    </inertial>
  </link>
  <joint name="base_chassis_joint" type="fixed">
    <origin rpy="0 0 1.5708" xyz="0.15 0 0"/>
    <parent link="base_link"/>
    <child link="chassis_link"/>
  </joint>
  <!-- Projection of base_link on the ground to get the 3D data
in the right frame w.r.t the ground. -->
  <link name="base_footprint">
    <inertial>
      <origin rpy="0 0 0" xyz="0 0 0"/>
      <mass value="1"/>
      <inertia ixx="0.2" ixy="0" ixz="0" iyy="0.2" iyz="0" izz="0.2"/>
    </inertial>
  </link>
  <joint name="base_footprint_joint" type="fixed">
    <origin rpy="0 0 0" xyz="0 0 -0.08"/>
    <parent link="base_link"/>
    <child link="base_footprint"/>
  </joint>
  <!-- Link for the position of the laser. -->
  <link name="front_laser">
    <inertial>
      <origin rpy="0 0 0" xyz="0 0 0"/>
      <mass value="1"/>
      <inertia ixx="0.2" ixy="0" ixz="0" iyy="0.2" iyz="0" izz="0.2"/>
    </inertial>
  </link>
  <joint name="base_laser_joint" type="fixed">
    <!-- LIDAR is moved forward slightly, from 0.407, to mitigate collision with internal_link due to slow physics updates  -->
    <origin rpy="3.14159 0 0" xyz="0.44 0 0.172"/>
    <parent link="base_link"/>
    <child link="front_laser"/>
  </joint>
  <!-- Stereo camera link to base_link. -->
  <link name="stereo">
    <inertial>
      <origin rpy="0 0 0" xyz="0 0 0"/>
      <mass value="1"/>
      <inertia ixx="0.2" ixy="0" ixz="0" iyy="0.2" iyz="0" izz="0.2"/>
    </inertial>
  </link>
  <joint name="stereo_camera_joint" type="fixed">
    <origin rpy="3.14159 0 0" xyz="0.4884 0 0.05465"/>
    <parent link="base_link"/>
    <child link="stereo"/>
  </joint>
  <link name="stereo_left">
    <inertial>
      <origin rpy="0 0 0" xyz="0 0 0"/>
      <mass value="1"/>
      <inertia ixx="0.2" ixy="0" ixz="0" iyy="0.2" iyz="0" izz="0.2"/>
    </inertial>
  </link>
  <joint name="stereo_left_joint" type="fixed">
    <origin rpy="-1.570796327 0 -1.570796327" xyz="0 0.060 0"/>
    <parent link="stereo"/>
    <child link="stereo_left"/>
  </joint>
  <link name="stereo_right">
    <inertial>
      <origin rpy="0 0 0" xyz="0 0 0"/>
      <mass value="1"/>
      <inertia ixx="0.2" ixy="0" ixz="0" iyy="0.2" iyz="0" izz="0.2"/>
    </inertial>
  </link>
  <joint name="stereo_right_joint" type="fixed">
    <origin rpy="-1.570796327 0 -1.570796327" xyz="0 -0.060 0"/>
    <parent link="stereo"/>
    <child link="stereo_right"/>
  </joint>
  <!-- Sonar links to base link joints -->
  <link name="rear_left_sonar_link">
    <inertial>
      <origin rpy="0 0 0" xyz="0 0 0"/>
      <mass value="1"/>
      <inertia ixx="0.2" ixy="0" ixz="0" iyy="0.2" iyz="0" izz="0.2"/>
    </inertial>
  </link>
  <joint name="rear_left_sonar_joint" type="fixed">
    <origin rpy="0 0 3.14159" xyz="-0.2043 0.150 0.157"/>
    <parent link="base_link"/>
    <child link="rear_left_sonar_link"/>
  </joint>
  <link name="rear_right_sonar_link">
    <inertial>
      <origin rpy="0 0 0" xyz="0 0 0"/>
      <mass value="1"/>
      <inertia ixx="0.2" ixy="0" ixz="0" iyy="0.2" iyz="0" izz="0.2"/>
    </inertial>
  </link>
  <transmission name="wheel_left_transmission">
    <type>transmission_interface/SimpleTransmission</type>
    <joint name="wheel_left_joint">
      <hardwareInterface>hardware_interface/VelocityJointInterface</hardwareInterface>
    </joint>
    <actuator name="wheel_left_actuator">
      <mechanicalReduction>1</mechanicalReduction>
    </actuator>
  </transmission>
  <transmission name="wheel_right_transmission">
    <type>transmission_interface/SimpleTransmission</type>
    <joint name="wheel_right_joint">
      <hardwareInterface>hardware_interface/VelocityJointInterface</hardwareInterface>
    </joint>
    <actuator name="wheel_right_actuator">
      <mechanicalReduction>1</mechanicalReduction>
    </actuator>
  </transmission>
  <joint name="rear_right_sonar_joint" type="fixed">
    <origin rpy="0 0 3.141597" xyz="-0.2043 -0.150 0.157"/>
    <parent link="base_link"/>
    <child link="rear_right_sonar_link"/>
  </joint>
  <link name="imu_link">
    <inertial>
      <origin rpy="0 0 0" xyz="0 0 0"/>
      <mass value="10"/>
      <inertia ixx="0.50" ixy="0" ixz="0" iyy="0.50" iyz="0" izz="1.00"/>
    </inertial>
  </link>
  <joint name="imu_joint" type="fixed">
    <parent link="base_link"/>
    <child link="imu_link"/>
    <origin rpy="0 0 -0.78539816339744828" xyz="0.191959 -0.086412 0.18455965360"/>
  </joint>
  <joint name="mmrobot_joint_top_mount" type="fixed">
    <parent link="top_mount"/>
    <child link="mmrobot_link0"/>
    <origin rpy="0 0 0" xyz="-0.15 0 0"/>
  </joint>
  <!-- end for simulation -->
  <link name="mmrobot_link0">
    <visual>
      <geometry>
        <mesh filename="meshes/visual/link0.dae"/>
      </geometry>
    </visual>
    <collision>
      <geometry>
        <mesh filename="meshes/collision/link0.stl"/>
      </geometry>
    </collision>
    <!-- for simulation -->
    <inertial>
      <origin rpy="0 0 0" xyz="0 0 0"/>
      <mass value="3.06"/>
      <inertia ixx="0.3" ixy="0.0" ixz="0.0" iyy="0.3" iyz="0.0" izz="0.3"/>
    </inertial>
    <!-- end for simulation -->
  </link>
  <link name="mmrobot_link1">
    <visual>
      <geometry>
        <mesh filename="meshes/visual/link1.dae"/>
      </geometry>
    </visual>
    <collision>
      <geometry>
        <mesh filename="meshes/collision/link1.stl"/>
      </geometry>
    </collision>
    <!-- for simulation -->
    <inertial>
      <origin rpy="0 0 0" xyz="0 0 0"/>
      <mass value="2.34"/>
      <inertia ixx="0.3" ixy="0.0" ixz="0.0" iyy="0.3" iyz="0.0" izz="0.3"/>
    </inertial>
    <!-- end for simulation -->
  </link>
  <joint name="mmrobot_joint1" type="revolute">
    <safety_controller k_position="100.0" k_velocity="40.0" soft_lower_limit="-2.8973" soft_upper_limit="2.8973"/>
    <origin rpy="0 0 0" xyz="0 0 0.333"/>
    <parent link="mmrobot_link0"/>
    <child link="mmrobot_link1"/>
    <axis xyz="0 0 1"/>
    <limit effort="87" lower="-2.8973" upper="2.8973" velocity="2.1750"/>
    <!-- for simulation -->
    <dynamics damping="1.0"/>
    <!-- end for simulation -->
  </joint>
  <link name="mmrobot_link2">
    <visual>
      <geometry>
        <mesh filename="meshes/visual/link2.dae"/>
      </geometry>
    </visual>
    <collision>
      <geometry>
        <mesh filename="meshes/collision/link2.stl"/>
      </geometry>
    </collision>
    <!-- for simulation -->
    <inertial>
      <origin rpy="0 0 0" xyz="0 0 0"/>
      <mass value="2.36"/>
      <inertia ixx="0.3" ixy="0.0" ixz="0.0" iyy="0.3" iyz="0.0" izz="0.3"/>
    </inertial>
    <!-- end for simulation -->
  </link>
  <joint name="mmrobot_joint2" type="revolute">
    <safety_controller k_position="100.0" k_velocity="40.0" soft_lower_limit="-1.7628" soft_upper_limit="1.7628"/>
    <origin rpy="-1.57079632679 0 0" xyz="0 0 0"/>
    <parent link="mmrobot_link1"/>
    <child link="mmrobot_link2"/>
    <axis xyz="0 0 1"/>
    <limit effort="87" lower="-1.7628" upper="1.7628" velocity="2.1750"/>
    <!-- for simulation -->
    <dynamics damping="1.0"/>
    <!-- end for simulation -->
  </joint>
  <link name="mmrobot_link3">
    <visual>
      <geometry>
        <mesh filename="meshes/visual/link3.dae"/>
      </geometry>
    </visual>
    <collision>
      <geometry>
        <mesh filename="meshes/collision/link3.stl"/>
      </geometry>
    </collision>
    <!-- for simulation -->
    <inertial>
      <origin rpy="0 0 0" xyz="0 0 0"/>
      <mass value="2.38"/>
      <inertia ixx="0.3" ixy="0.0" ixz="0.0" iyy="0.3" iyz="0.0" izz="0.3"/>
    </inertial>
    <!-- end for simulation -->
  </link>
  <joint name="mmrobot_joint3" type="revolute">
    <safety_controller k_position="100.0" k_velocity="40.0" soft_lower_limit="-2.8973" soft_upper_limit="2.8973"/>
    <origin rpy="1.57079632679 0 0" xyz="0 -0.316 0"/>
    <parent link="mmrobot_link2"/>
    <child link="mmrobot_link3"/>
    <axis xyz="0 0 1"/>
    <limit effort="87" lower="-2.8973" upper="2.8973" velocity="2.1750"/>
    <!-- for simulation -->
    <dynamics damping="1.0"/>
    <!-- end for simulation -->
  </joint>
  <link name="mmrobot_link4">
    <visual>
      <geometry>
        <mesh filename="meshes/visual/link4.dae"/>
      </geometry>
    </visual>
    <collision>
      <geometry>
        <mesh filename="meshes/collision/link4.stl"/>
      </geometry>
    </collision>
    <!-- for simulation -->
    <inertial>
      <origin rpy="0 0 0" xyz="0 0 0"/>
      <mass value="2.43"/>
      <inertia ixx="0.3" ixy="0.0" ixz="0.0" iyy="0.3" iyz="0.0" izz="0.3"/>
    </inertial>
    <!-- end for simulation -->
  </link>
  <joint name="mmrobot_joint4" type="revolute">
    <safety_controller k_position="100.0" k_velocity="40.0" soft_lower_limit="-1.50100" soft_upper_limit="1.500996"/>
    <!-- changed joint init position to be closer to home position-->
    <origin rpy="1.57079632679 1.57079632679 0" xyz="0.0825 0 0"/>
    <parent link="mmrobot_link3"/>
    <child link="mmrobot_link4"/>
    <axis xyz="0 0 1"/>
    <limit effort="87" lower="-1.50100" upper="1.500996" velocity="2.1750"/>
    <!-- for simulation -->
    <dynamics damping="1.0"/>
    <!-- end for simulation -->
  </joint>
  <link name="mmrobot_link5">
    <visual>
      <geometry>
        <mesh filename="meshes/visual/link5.dae"/>
      </geometry>
    </visual>
    <collision>
      <geometry>
        <mesh filename="meshes/collision/link5.stl"/>
      </geometry>
    </collision>
    <!-- for simulation -->
    <inertial>
      <origin rpy="0 0 0" xyz="0 0 0"/>
      <mass value="3.5"/>
      <inertia ixx="0.3" ixy="0.0" ixz="0.0" iyy="0.3" iyz="0.0" izz="0.3"/>
    </inertial>
    <!-- end for simulation -->
  </link>
  <joint name="mmrobot_joint5" type="revolute">
    <safety_controller k_position="100.0" k_velocity="40.0" soft_lower_limit="-2.8973" soft_upper_limit="2.8973"/>
    <origin rpy="-1.57079632679 0 0" xyz="-0.0825 0.384 0"/>
    <parent link="mmrobot_link4"/>
    <child link="mmrobot_link5"/>
    <axis xyz="0 0 1"/>
    <limit effort="12" lower="-2.8973" upper="2.8973" velocity="2.6100"/>
    <!-- for simulation -->
    <dynamics damping="1.0"/>
    <!-- end for simulation -->
  </joint>
  <link name="mmrobot_link6">
    <visual>
      <geometry>
        <mesh filename="meshes/visual/link6.dae"/>
      </geometry>
    </visual>
    <collision>
      <geometry>
        <mesh filename="meshes/collision/link6.stl"/>
      </geometry>
    </collision>
    <!-- for simulation -->
    <inertial>
      <origin rpy="0 0 0" xyz="0 0 0"/>
      <mass value="1.47"/>
      <inertia ixx="0.3" ixy="0.0" ixz="0.0" iyy="0.3" iyz="0.0" izz="0.3"/>
    </inertial>
    <!-- end for simulation -->
  </link>
  <joint name="mmrobot_joint6" type="revolute">
    <safety_controller k_position="100.0" k_velocity="40.0" soft_lower_limit="-1.58830" soft_upper_limit="2.1817"/>
    <!-- changed values to be out of collision at start of simulation-->
    <origin rpy="1.57079632679 -1.57079632679 0" xyz="0 0 0"/>
    <parent link="mmrobot_link5"/>
    <child link="mmrobot_link6"/>
    <axis xyz="0 0 1"/>
    <limit effort="12" lower="-1.58830" upper="2.1817" velocity="2.6100"/>
    <!-- for simulation -->
    <dynamics damping="1.0"/>
    <!-- end for simulation -->
  </joint>
  <link name="mmrobot_link7">
    <visual>
      <geometry>
        <mesh filename="meshes/visual/link7.dae"/>
      </geometry>
    </visual>
    <collision>
      <geometry>
        <mesh filename="meshes/collision/link7.stl"/>
      </geometry>
    </collision>
    <!-- for simulation -->
    <inertial>
      <origin rpy="0 0 0" xyz="0 0 0"/>
      <mass value="0.45"/>
      <inertia ixx="0.3" ixy="0.0" ixz="0.0" iyy="0.3" iyz="0.0" izz="0.3"/>
    </inertial>
    <!-- end for simulation -->
  </link>
  <joint name="mmrobot_joint7" type="revolute">
    <safety_controller k_position="100.0" k_velocity="40.0" soft_lower_limit="-2.8973" soft_upper_limit="2.8973"/>
    <origin rpy="1.57079632679 0 0" xyz="0.088 0 0"/>
    <parent link="mmrobot_link6"/>
    <child link="mmrobot_link7"/>
    <axis xyz="0 0 1"/>
    <limit effort="12" lower="-2.8973" upper="2.8973" velocity="2.6100"/>
    <!-- for simulation -->
    <dynamics damping="1.0"/>
    <!-- end for simulation -->
  </joint>
  <link name="mmrobot_link8">
    <!-- for simulation -->
    <inertial>
      <origin rpy="0 0 0" xyz="0 0 0"/>
      <mass value="0.0"/>
      <inertia ixx="0.3" ixy="0.0" ixz="0.0" iyy="0.3" iyz="0.0" izz="0.3"/>
    </inertial>
    <!-- end for simulation -->
  </link>
  <joint name="mmrobot_joint8" type="fixed">
    <origin rpy="0 0 0" xyz="0 0 0.107"/>
    <parent link="mmrobot_link7"/>
    <child link="mmrobot_link8"/>
    <axis xyz="0 0 0"/>
  </joint>
  <joint name="mmrobot_hand_joint" type="fixed">
    <parent link="mmrobot_link8"/>
    <child link="mmrobot_hand"/>
    <origin rpy="0 0 -0.785398163397" xyz="0 0 0"/>
  </joint>
  <link name="mmrobot_hand">
    <visual>
      <geometry>
        <mesh filename="meshes/visual/hand.dae"/>
      </geometry>
    </visual>
    <collision>
      <geometry>
        <mesh filename="meshes/collision/hand.stl"/>
      </geometry>
    </collision>
    <!-- for simulation -->
    <inertial>
      <origin rpy="0 0 0" xyz="0 0 0"/>
      <mass value="0.68"/>
      <inertia ixx="0.1" ixy="0.0" ixz="0.0" iyy="0.1" iyz="0.0" izz="0.1"/>
    </inertial>
    <!-- end for simulation -->
  </link>
  <link name="mmrobot_leftfinger">
    <visual>
      <geometry>
        <mesh filename="meshes/visual/finger.dae"/>
      </geometry>
    </visual>
    <collision>
      <geometry>
        <mesh filename="meshes/collision/finger.stl"/>
      </geometry>
    </collision>
    <!-- for simulation -->
    <inertial>
      <origin rpy="0 0 0" xyz="0 0 0"/>
      <mass value="0.01"/>
      <inertia ixx="0.1" ixy="0.0" ixz="0.0" iyy="0.1" iyz="0.0" izz="0.1"/>
    </inertial>
    <!-- end for simulation -->
  </link>
  <link name="mmrobot_rightfinger">
    <visual>
      <origin rpy="0 0 3.14159265359" xyz="0 0 0"/>
      <geometry>
        <mesh filename="meshes/visual/finger.dae"/>
      </geometry>
    </visual>
    <collision>
      <origin rpy="0 0 3.14159265359" xyz="0 0 0"/>
      <geometry>
        <mesh filename="meshes/collision/finger.stl"/>
      </geometry>
    </collision>
    <!-- for simulation -->
    <inertial>
      <origin rpy="0 0 0" xyz="0 0 0"/>
      <mass value="0.01"/>
      <inertia ixx="0.1" ixy="0.0" ixz="0.0" iyy="0.1" iyz="0.0" izz="0.1"/>
    </inertial>
    <!-- end for simulation -->
  </link>
  <joint name="mmrobot_finger_joint1" type="prismatic">
    <parent link="mmrobot_hand"/>
    <child link="mmrobot_leftfinger"/>
    <origin rpy="0 0 0" xyz="0 0 0.0584"/>
    <axis xyz="0 1 0"/>
    <limit effort="20" lower="0.0" upper="0.04" velocity="0.2"/>
  </joint>
  <joint name="mmrobot_finger_joint2" type="prismatic">
    <parent link="mmrobot_hand"/>
    <child link="mmrobot_rightfinger"/>
    <origin rpy="0 0 0" xyz="0 0 0.0584"/>
    <axis xyz="0 -1 0"/>
    <limit effort="20" lower="0.0" upper="0.04" velocity="0.2"/>
  </joint>
  <!-- Link0 -->
</robot>

